Workbook
Name Adressenliste: 'Adressdaten'!$A$5:$V$173
Name Mailingliste: 'Mailingdaten'!$A$5:$F$173

Sheet Exportdaten
H1: Export durchgeführt am: | J1: 46080.679
H2: Auftraggeber: | J2: Thomas Humitsch
H3: Grund: | J3: Anderer Grund Standesführung Mitarbeiterdaten aktualisieren | AG3: Zustelladresse
A5: CbrPoint | B5: LaufendeNummer | C5: Anrede | D5: Berufstitel | E5: AkademischerGrad | F5: VornamePrae | G5: Vorname | H5: Vorname2 | I5: VornamePost | J5: NachnamePrae | K5: Nachname | L5: NachnamePost | M5: Orden | N5: PostgradualerTitel | O5: Couleurname | P5: Anmerkungen | Q5: Leibbursch | R5: Urverbindung | S5: Mitgliedstatus | T5: Reception | U5: Branderung | V5: Burschung | W5: Philistrierung | X5: Austritt | Y5: Kalkül | Z5: Geburtsdatum | AA5: Geburtsort | AB5: Sterbedatum | AC5: SterbeOrt | AD5: SterbeDetails | AE5: Akademia Versand | AF5: Verbindungszeitung | AG5: Adresstyp | AH5: Strasse | AI5: PLZ | AJ5: Ort | AK5: co1 | AL5: co2 | AM5: Land | AN5: Bundesland | AO5: Mobil Privat | AP5: Mobil Dienstlich | AQ5: Telefon Sonstige | AR5: E-Mail | AS5: Studien | AT5: Berufe | AU5: Ehrungen | AV5: Chargen | AW5: AktuelleChargen | AX5: Mitgliedschaften ÖCV | AY5: Mitgliedschaften MKV | AZ5: Mitgliedschaften CV | BA5: Mitgliedschaften Andere
A6: 10500102 | C6: Herrn | G6: Maximilian | H6: Joseph Andreas | K6: Amort | O6: Stoiber | Q6: Paul Melbinger v. Zippo | R6: Alb | S6: UP | T6: 02.12.2011 | U6: 22.06.2012 | V6: 01.02.2013 | W6: 04.03.2024 | Y6: Mitgliedschaft ist aufrecht | Z6: 17.03.1990 | AA6: Berchtesgaden | AE6: elektronisch | AF6: postalisch | AG6: Privatadresse | AH6: 38, rue de la Corniche | AI6: 5956 | AJ6: Itzig | AM6: LUXEMBURG | AO6: +352 621 572088 | AR6: maximilian.amort@gmail.com | AS6: - Wirtschaftsingenieurwesen - Maschinenbau (TU Graz) | - Maschinenbau (Uni im Ausland) | AV6: Alb:Schriftführer (SS 2013) | Alb:Consenior (WS 2013/14) | Alb:Fuchsmajor (SS 2014) | AX6: Alb v. Stoiber (UP:2.12.2011) | AY6: IVS v. Cervus (UP:12.3.2010), NMG v. Cervus (BP:9.2.2013), AMV v. Cervus (BP:6.4.2013) | BA6: IVS v. Cervus (UP:12.3.2010), NMG v. Cervus (BP:9.2.2013), AMV v. Cervus (BP:6.4.2013)
A7: 10500150 | C7: Herrn | E7: Dr. | G7: Engelbert | K7: Aspeck | O7: Paracelsus | R7: Alb | S7: UP | T7: 06.10.1992 | V7: 08.10.1993 | W7: 19.04.2007 | Y7: Mitgliedschaft ist aufrecht | Z7: 11.04.1970 | AE7: elektronisch | AF7: postalisch | AG7: Privatadresse | AH7: Unterer Plattenweg 65 | AI7: 8043 | AJ7: Graz | AM7: ÖSTERREICH | AN7: STMK | AO7: +43 664 4012509 | AR7: engelbert.aspeck@outlook.com | AS7: 1989 - Medizin - keine Angabe (Uni Graz) | AT7: Öffentlicher Dienst - Spitäler, Rehab., Kuranst. u. dgl. - Landeskrankenhäuser-Assistenzarzt-LKH Graz, Univ. Klinik f. Neurologie | AU7: Alb 50-Semester Jubelband (28.10.2017) | AX7: Alb v. Paracelsus (UP:6.10.1992) | AY7: AMV v. Paracelsus (UP:8.4.2000) | BA7: AMV v. Paracelsus (UP:8.4.2000)
A8: 10500310 | C8: Herrn | G8: Gerald | K8: Baumschlager | N8: BSc | O8: HalloElke | Q8: Michael Franz Eibl v. Betöng | R8: Alb | S8: BU | T8: 01.10.2021 | U8: 09.07.2022 | V8: 10.03.2023 | Y8: Mitgliedschaft ist aufrecht | Z8: 22.02.1997 | AA8: Kirchdorf a.d. Krems | AE8: elektronisch | AF8: postalisch | AG8: Privatadresse | AH8: Kettengasse 3b / 14 | AI8: 8010 | AJ8: Graz | AM8: ÖSTERREICH | AN8: STMK | AO8: +43 664 3486600 | AR8: gerald.baumschlager@gmail.com | AS8: 2015 - 2020 Biomedical Engineering (VetMed Wien) | 2021 - Biotechnologie (TU Graz) | AV8: Alb:Barwart (WS 2022/23) | Alb:Kassier (SS 2023) | Alb:Kassier (SS 2024) | GCV:OV-Vizepräsident 2 (Von 01. Jul. 2024 bis 30. Jun. 2025) | Alb:Fuchsmajor (WS 2025/26) | AX8: Alb v. HalloElke (BU:1.10.2021)
A9: 10500298 | C9: Herrn | G9: Matthias | K9: Berger | O9: HengtBoss | Q9: Maximilian Grillitsch v. Baking Bread | R9: Alb | S9: BU | T9: 27.10.2018 | U9: 24.05.2019 | V9: 04.10.2019 | Y9: Mitgliedschaft ist aufrecht | Z9: 27.07.1995 | AA9: Kirchdorf | AE9: elektronisch | AF9: postalisch | AG9: Privatadresse | AH9: Raimundgasse 2/1 | AI9: 8010 | AJ9: Graz | AM9: ÖSTERREICH | AN9: STMK | AO9: +43 660 7688671 | AR9: bergermatthias95@gmail.com | AS9: 2016 - 2022 Betriebswirtschaft - keine Angabe (Uni Graz) | 2022 - Wirtschaftsinformatik - Betriebswirtschaft (Uni Graz) | AT9: Privatwirtschaft - Dienstleistung - Banken-Angestellter - Finanzierungen/Investitionen-Financial Analyst | AV9: Alb:Kassier (WS 2019/20) | Alb:Kassier (SS 2020) | Alb:Senior (WS 2020/21) | Alb:Fuchsmajor 2 (SS 2021) | AX9: Alb v. HengtBoss (BU:27.10.2018) | AY9: GTS (BU:), ASG (VA:), OPK (BI:) | BA9: GTS (BU:), ASG (VA:), OPK (BI:)
A10: 10500022 | C10: Herrn | E10: DI (FH) | G10: David | K10: Binder | O10: Kojak II. | Q10: Bernhard Kainz v. Schäpfer | R10: Alb | S10: UP | T10: 22.05.2003 | V10: 30.10.2004 | W10: 28.10.2006 | Y10: Mitgliedschaft ist aufrecht | Z10: 17.10.1980 | AA10: Graz | AE10: postalisch | AF10: postalisch | AG10: Privatadresse | AH10: Dorfstraße 58 | AI10: 8403 | AJ10: Sankt Margarethen bei Lebring | AM10: ÖSTERREICH | AN10: STMK | AO10: +43 664 1344558 | AQ10: Telefon dienstlich:+43 316 269747-21 | AR10: david.binder@gmx.at | AS10: 2000 - 2004 Informationsmanagement (FH Joanneum) | AT10: Privatwirtschaft - Dienstleistung - IT-Angestellter - Geschäftsführer - Geschäftsleitung/Management- | AV10: Alb:Consenior (WS 2004/05) | Alb:Fuchsmajor (SS 2005) | Alb:Fuchsmajor (WS 2005/06) | AX10: Alb v. Kojak II. (UP:22.5.2003) | AY10: LRG v. Kojak (BP:_._.1999), RBF v. Kojak (UP:_.12.1996), SOW v. Kojak (BP:_._.2006) | BA10: LRG v. Kojak (BP:_._.1999), RBF v. Kojak (UP:_.12.1996), SOW v. Kojak (BP:_._.2006)
A11: 13101359 | C11: Herrn | D11: RA | E11: Mag. | G11: Stefan | H11: Albert | K11: Blümke | O11: Pizzi | R11: R-J | S11: UP | T11: 24.05.1997 | V11: 09.10.1998 | W11: 07.10.2008 | Y11: Mitgliedschaft ist aufrecht | Z11: 05.05.1978 | AE11: postalisch | AF11: postalisch | AG11: Privatadresse | AH11: Bergerweg 3 | AI11: 4212 | AJ11: Neumarkt im Mühlkreis | AM11: ÖSTERREICH | AN11: OÖ | AO11: +43 650 6261984 | AR11: bluemke@bssk.at | AS11: 0 - 0 Rechtswissenschaften - Doktoratsstudium der Rechtswissenschaften (Uni Salzburg) | AT11: Öffentliche Wirtschaft - Soziale Verwaltung - Sozialversicherung-Referent - Recht- | AV11: GCV:OV-Präsident (Von 01. Jul. 2001 bis 30. Jun. 2002) | R-J:Senior (SS 2003) | R-J:Fuchsmajor (SS 2005) | SCV:OV-Präsident (Von 26. Sep. 2007 bis 30. Jun. 2008) | Ma:Philisterconsenior 2 (Von 29. Nov. 2014 bis 30. Jun. 2017) | AX11: R-J v. Pizzi (UP:24.5.1997), Alb v. Pizzi (BP:_._.2002), Ma v. Pizzi (EP:29.11.2014)
A12: 10500121 | C12: Herrn | E12: Dr. | G12: Reinhold | K12: Böhler | O12: Cid | R12: Alb | S12: UP | T12: 06.11.1963 | V12: 13.04.1964 | Y12: Mitgliedschaft ist aufrecht | Z12: 12.05.1940 | AE12: postalisch | AF12: postalisch | AG12: Privatadresse | AH12: Schulweg 5A | AI12: 6973 | AJ12: Höchst | AM12: ÖSTERREICH | AN12: V | AO12: +43 664 1605378 | AQ12: Telefon privat:+43 5578 77399 Fax privat:+43 5522 32653 | AR12: boehler.reinhold@gmail.com | AS12: 0 - 0 Medizin - keine Angabe | AT12: Freie Berufe - Arzt-Pensionist/im Ruhestand - Freiberufler - Bereichsleitung- | AX12: Alb v. Cid (UP:6.11.1963)
A13: 10500100 | C13: Herrn | D13: Prof. | E13: Mag. | G13: Gebhard | K13: Brandweiner | O13: SichaNet | Q13: Heribert Probst v. Yoda | R13: Alb | S13: UP | T13: 29.10.2011 | U13: 03.03.2012 | V13: 22.06.2012 | W13: 23.10.2021 | Y13: Mitgliedschaft ist aufrecht | Z13: 28.11.1990 | AA13: Hallein | AE13: postalisch | AF13: postalisch | AG13: Privatadresse | AH13: Schillerstraße 27a/1 | AI13: 8010 | AJ13: Graz | AM13: ÖSTERREICH | AN13: STMK | AO13: +43 660 1424909 | AR13: sichanet@albertina-graz.at | AS13: 2011 - 2012 Fachtheologie (Katholische Theologie) - keine Angabe (Uni Graz) | 2013 - 2021 Kombinierte Religionspädagogik (Katholische Theologie) - Geschichte Studienzweig: Geschichte und Sozialkunde (Lehramt) (Uni Graz) | AT13: Öffentlicher Dienst - Schulen-Lehrer/Prof. (Uni. und/oder Schule) - Religion/Theologie-Lehrer | AU13: Alb Dank-Band (26.10.2024) | AV13: Alb:Barwart 1 (SS 2012) | GCV:OV-Präsident (Von 01. Jul. 2014 bis 30. Jun. 2015) | Alb:Fuchsmajor (SS 2016) | Alb:Senior (WS 2016/17) | Alb:Schriftführer (WS 2020/21) | Alb:Schriftführer (SS 2021) | AHLB STMK:AHLB-Schriftführer (Ab 01. Mrz. 2025) | ÖCV:AHS-Referent (Ab 01. Jul. 2025) | Alb:Standesführer ÖCV.Net (Ab 26. Jan. 2026) | Alb:Fuchsmajor 2 (SS 2026) | AW13: AHLB STMK:AHLB-Schriftführer (Ab 01. Mrz. 2025) | ÖCV:AHS-Referent (Ab 01. Jul. 2025) | Alb:Fuchsmajor 2 (SS 2026) | Alb:Standesführer ÖCV.Net (Ab 26. Jan. 2026) | AX13: Alb v. SichaNet (UP:29.10.2011) | AY13: ILH v. Philos (UP:23.9.2006), ASG v. Philos (BP:29.6.2012), PLP v. Philos (EM:6.12.2025) | BA13: ILH v. Philos (UP:23.9.2006), ASG v. Philos (BP:29.6.2012), PLP v. Philos (EM:6.12.2025)
A14: 11100786 | B14: 786 | C14: Herrn | D14: Gschf. | E14: Dipl.-Ing. | G14: Gernot | K14: Brandweiner | N14: MBA | O14: Stiel | P14: 13.02.1956: Ehe mit Gunda, Kinder: Gernot (* 1984), Gudrun (* 1986), Gebhard (* ...) | 13.02.1956: Unter seinem Seniorat im SS 78 wurde die ursprünglich von Cbr. Kurt Melchard v/o Goggo (NbW) als Verkehrsaktiver 1968 begründete Verbindungszeitung "Der Standpunkt" mit dem neuen Namen "Convent" wieder aktiviert und bildet seither einen fixen Bestandteil der verbindungsinternen Kommunikation. Der "Convent" wurde danach über mehrere Jahre von Peter Rindler v/o Mahlzeit redigiert. (siehe auch BbG-Verbindungsbuch 1980, Seite 57 und 80). | | Q14: Albert Wogrolly (Dim) v. Schnucki | R14: BbG | S14: UP | T14: 24.06.1976 | V14: 01.06.1977 | W14: 25.01.1983 | Y14: Mitgliedschaft ist aufrecht | Z14: 13.02.1956 | AA14: Hallein | AE14: postalisch | AF14: postalisch | AG14: Privatadresse | AH14: Krispl 70 | AI14: 5425 | AJ14: Krispl | AM14: ÖSTERREICH | AO14: +43 676 5805461 | AQ14: Fax privat:+43 6240 520 Telefon privat:+43 6240 520 | AR14: brandweiner_gernot@outlook.com | AS14: 1975 - 1981 Vermessungswesen - keine Angabe (TU Graz) | 1995 - 1997 Master of Business Administration - keine Angabe (Uni Krems) | AT14: Privatwirtschaft - Industrie - Bau und Baustoffe-Pensionist/im Ruhestand - Geschäftsführer-Geschäftsführer / VÖB - Verband österr. Beton- u. Fertigteilwerke, Wien | AU14: BbG 50-Semester Jubelband (16.06.2001) | BbG 75-Semester Jubelband (21.06.2014) | AV14: BbG:Kassier 2 (SS 1977) | BbG:Senior (SS 1978) | AHLB S:AHLB-Vorsitzender (Von 20. Nov. 1998 bis 28. Nov. 2003) | ÖCV:Vors. des AHLR und 1. Stv. Vors. der AHS (Von 01. Jul. 2003 bis 25. Mai. 2006) | AX14: BbG v. Stiel (UP:24.6.1976), Alb v. Stiel (BP:_._.1979), Rp v. Stiel (BP:23.6.2001) | AY14: ILH v. Stiel (EP:14.10.1989) | BA14: ILH v. Stiel (EP:14.10.1989)
A15: 10500044 | C15: Herrn | D15: FA | E15: Dr. | G15: Viktor | K15: Brudniak | O15: Ex | R15: Alb | S15: UP | T15: 27.10.1979 | V15: 25.11.1980 | W15: 1990 | Y15: Mitgliedschaft ist aufrecht | Z15: 05.10.1960 | AE15: postalisch | AF15: postalisch | AG15: Privatadresse | AH15: Kresbach 138 | AI15: 8530 | AJ15: Deutschlandsberg | AM15: ÖSTERREICH | AN15: STMK | AQ15: Telefon privat:+43 3462 7983 Fax dienstlich:+43 3462 7711-14 Telefon dienstlich:+43 3462 7711-13 | AR15: viktor.brudniak@gmx.at | AS15: 1979 - Medizin - keine Angabe (Uni Graz) | AT15: Freie Berufe - Arzt - FA für Lungenheilkunde-- | AX15: Alb v. Ex (UP:27.10.1979)
A16: 10500229 | C16: Herrn | D16: RA | E16: Mag. Dr. | G16: Lukas | K16: Charisius | O16: Enrico | Q16: Martin Fimberger v. Freibier | R16: Alb | S16: UP | T16: 30.01.1995 | V16: 06.10.1996 | W16: 19.04.2007 | Y16: Mitgliedschaft ist aufrecht | Z16: 24.04.1976 | AE16: postalisch | AF16: postalisch | AG16: Privatadresse | AH16: Max-Valier-Straße 24 | AI16: 39100 | AJ16: Bozen | AM16: ITALIEN | AO16: +39 339 2355963 | AQ16: Telefon privat:+39 0471 402183 Telefon dienstlich:+39 0471 344123 | AR16: lukas.charisius@jus.cc | AS16: 1994 - Rechtswissenschaften - keine Angabe (Uni Graz) | 1996 - Soziologie - Geisteswissenschaftlicher Studienzweig (Uni Graz) | AT16: Privatwirtschaft - Industrie - Nahrungs- und Genußmittel-Jurist- | AX16: Alb v. Enrico (UP:30.1.1995)
A17: 12200062 | C17: Herrn | E17: Dr. | G17: Markus | K17: Charisius | O17: Merlin | R17: Lo | S17: UP | T17: 09.10.1990 | U17: 29.06.1991 | V17: 05.10.1991 | W17: 07.03.2006 | Y17: Mitgliedschaft ist aufrecht | Z17: 21.03.1972 | AA17: Salzburg | AE17: elektronisch | AF17: postalisch | AO17: +43 664 5365843 | AQ17: Telefon dienstlich:+43 4244 22155 | AR17: markus.charisius@gmail.com | AS17: 1990 - 1991 Rechtswissenschaften - keine Angabe (Uni Salzburg) | 1991 - 1994 Medizin - keine Angabe (Uni Graz) | 1994 - 1995 Psychologie - keine Angabe (Uni Graz) | 1995 - 2003 Medizin - keine Angabe (Uni Wien) | 2004 - Medizin - keine Angabe (Uni Wien) | AT17: Freie Berufe - Arzt - Praktischer Arzt (Allgemeinmed.)-Selbständiger- | AU17: Lo 50-Semester Jubelband (07.10.2017) | AV17: Merc:Schriftführer (SS 2002) | AX17: Lo v. Merlin (UP:9.10.1990), Alb v. Merlin (BP:27.6.1992), Merc v. Merlin (BP:8.1.2002)
A18: 11100766 | B18: 766 | C18: Herrn | D18: HR KADir. i.R. | E18: Mag. Mag. Dr. | G18: Rudolf | K18: Dörflinger | O18: Prost | P18: 10.07.1953: Ehe mit Evelin, | 10.07.1953: Co-Organisator des BbG-Treffens in St. Georgen am Längsee / Kärnten mit Bernhard Wenger v/o Faun am 16./17.10.2004 | | Q18: Gerhard Lammer v. Taurus | R18: BbG | S18: UP | T18: 16.10.1975 | V18: Jun. 1976 | W18: 14.12.1979 | Y18: Mitgliedschaft ist aufrecht | Z18: 10.07.1953 | AA18: St. Veit a.d. Glan | AE18: postalisch | AF18: postalisch | AG18: Privatadresse | AH18: Thalsdorf 39 | AI18: 9314 | AJ18: Launsdorf | AM18: ÖSTERREICH | AN18: K | AO18: +43 676 89903000 | AQ18: Telefon privat:+43 4213 3038 Fax privat:+43 4213 3038 Telefon privat:+43 4265 8390 Telefon dienstlich:+43 463 5870-419 Telefon dienstlich:+43 463 5870-423 Fax dienstlich:+43 463 5870-420 | AR18: rudolf@r-doerflinger.at | AS18: 1972 - 1979 Germanistik (Uni Graz) | 1979 - 1986 Rechtswissenschaften - keine Angabe (Uni Graz) | AT18: Körperschaften/Verbände - Gesetzl. Berufsvertretungen (Kammern)-Angestellter - Mitgl. d. Vorst., Geschäftsl. oder Direktion- | Körperschaften/Verbände - Katholische Kirche - Diözese Gurk-Klagenfurt-(Ehrenamt.) Funktionär - Pfarrgemeinderat - Seelsorge-Ersatz-Pfarrgemeinderat in der Pfarre St. Georgen am Längsee | AU18: BbG 50-Semester Jubelband (01.06.2002) | BbG 75-Semester Jubelband (01.06.2013) | AV18: Alb:Fuchsmajor (Von 01. Mrz. 1979 bis 29. Jun. 1979) | GCV:OV-Präsident (Von 01. Jul. 1979 bis 30. Jun. 1980) | AX18: BbG v. Prost (UP:16.10.1975), Alb v. Prost (EP:13.10.1981), Ca v. Prost (EP:14.12.2002) | AY18: GOA v. Orpheus (UP:_._.1969), GLK v. Orpheus (BP:_._.1996) | BA18: GOA v. Orpheus (UP:_._.1969), GLK v. Orpheus (BP:_._.1996)
A19: 10500004 | C19: Herrn | D19: Abt.Ltr. | E19: Dr. | G19: Rudolf Christian | H19: Schnutz | K19: Dürr | O19: Magellan | R19: Alb | S19: UP | T19: 04.05.1984 | V19: 21.06.1985 | W19: 24.10.1992 | Y19: Mitgliedschaft ist aufrecht | Z19: 23.01.1964 | AA19: Bruck a.d. Mur | AE19: postalisch | AF19: postalisch | AG19: Privatadresse | AH19: 7 Rue Koenigsmann | AI19: 67000 | AJ19: Strasbourg | AM19: FRANKREICH | AO19: +33 6 61148062 | AQ19: Telefon privat:+33 388 310043 Telefon dienstlich:+33 388 413908 | AR19: schnutz.durr@gmail.com | AS19: 0 - 0 Doktoratsstudium der Rechtswissenschaften - keine Angabe (Uni Wien) | 1982 - Rechtswissenschaften - keine Angabe (Uni Graz) | AT19: Körperschaften/Verbände - Internationale Organisation - Europarat-Beamter - Abteilungsleiter - Verfassung-Head of Constitutional Justice Division, Venice Commission, Council of Europe | AX19: Alb v. Magellan (UP:4.5.1984), Nc v. Magellan (BP:)
A20: 10500289 | C20: Herrn | D20: Bgm. a.D. | G20: Michael Franz | K20: Eibl | O20: Betöng | Q20: Gebhard Brandweiner v. SichaNet | R20: Alb | S20: BU | T20: 28.10.2017 | U20: 09.03.2018 | V20: 27.10.2018 | Y20: Mitgliedschaft ist aufrecht | Z20: 18.03.1997 | AA20: Kirchdorf an der Krems | AE20: elektronisch | AF20: postalisch | AG20: Privatadresse | AH20: Krenngasse 7 | AI20: 8010 | AJ20: Graz | AM20: ÖSTERREICH | AN20: STMK | AO20: +43 664 1754025 | AR20: m.f.eibl@gmx.at | AS20: 2017 - Physik - keine Angabe (TU Graz) | AT20: Politischer Bereich - Gemeinderat, Stadtsenat o. dgl. - Oberösterreich-(Ehrenamt.) Funktionär-Bürgermeister von Windischgarsten a.D. | AV20: Alb:Kassier (SS 2019) | Alb:Senior (WS 2019/20) | GCV:OV-Präsident (Von 01. Jul. 2024 bis 24. Jan. 2025) | Alb:Fuchsmajor (SS 2026) | AW20: Alb:Fuchsmajor (SS 2026) | AX20: Alb v. Betöng (BU:28.10.2017) | AY20: OPK v. Warschus (BU:25.3.2016), ASG v. Warschus (BI:16.9.2017), GTS v. Warschus (BI:28.12.2024) | BA20: OPK v. Warschus (BU:25.3.2016), ASG v. Warschus (BI:16.9.2017), GTS v. Warschus (BI:28.12.2024)
A21: 10401117 | C21: Herrn | D21: HR | E21: Dipl.-Ing. | G21: Walter | K21: Erber | O21: Woidl | P21: 13.01.1950: GB 3008 | | Q21: Herbert Kain v. Abel | R21: AIn | S21: UP | T21: 23.01.1973 | V21: 15.01.1974 | W21: 10.01.1981 | Y21: Mitgliedschaft ist aufrecht | Z21: 13.01.1950 | AA21: Bad Ischl | AE21: postalisch | AF21: postalisch | AG21: Privatadresse | AH21: Steinfeldstraße 2A | AI21: 4820 | AJ21: Bad Ischl | AM21: ÖSTERREICH | AN21: OÖ | AO21: +43 650 66 20 837 | AR21: erber111@gmail.com | AS21: 1974 - 1980 Vermessungswesen (TU Graz) | AT21: Öffentliche Wirtschaft-Beamter - Amtsleiter - Verwaltung-Leiter des Vermessungsamtes Salzburg in Ruhe | AX21: AIn v. Woidl (UP:23.1.1973), Alb v. Woidl (BP:25.11.1975) | AY21: WDI v. Woidl (UP:_._.1966) | BA21: WDI v. Woidl (UP:_._.1966)
A22: 11800199 | C22: Herrn | E22: Mag. Dr. | G22: Albrecht | K22: Erlacher | O22: Latte | P22: 31.01.1954: Ehe (+ 2007), Kinder: 2 Töchter, 2. Ehe 26.09.09 mit Mag. Edith Erlacher-Zeitlinger ; | 31.01.1954: Leibbursch: Golser v. Mozart | | R22: GlL | S22: UP | T22: 17.10.1972 | U22: 12.12.1972 | V22: 28.10.1973 | W22: 30.03.1981 | Y22: Mitgliedschaft ist aufrecht | Z22: 31.01.1954 | AA22: Raffelsdorf 1 | AE22: postalisch | AF22: postalisch | AG22: Privatadresse | AH22: Etruskerweg 26 | AI22: 9073 | AJ22: Klagenfurt | AM22: ÖSTERREICH | AN22: K | AO22: +43 664 1421387 | AR22: albrecht.erlacher1@gmail.com | AS22: 1972 - 1975 Kunststofftechnik - keine Angabe (Leoben, Montan Uni) | 1975 - 1981 Rechtswissenschaften - keine Angabe (Uni Graz) | AT22: --Koordinator Reininghaus | Öffentliche Wirtschaft - Kommunale Versorgung-außer Dienst - Projektleiter - Bauwesen-Reininghaus-Koordinator Stadt Graz | AU22: GlL 75-Semester Jubelband (08.05.2010) | GlL 100-Semester Jubelband (14.05.2022) | AV22: GlL:Schriftführer (WS 1974/75) | AX22: GlL v. Latte (UP:17.10.1972), Alb v. Lotte (BP:_._.1980), BbG v. Latte (BP:29.6.1978)
A23: 10500101 | C23: Herrn | D23: Prof. OStR. | E23: Dipl.-Ing. | G23: Felix | K23: Feldbacher | O23: Dr. cer. Tangens | R23: Alb | S23: UP | T23: 29.05.1961 | V23: 07.02.1962 | W23: 18.10.1966 | Y23: Mitgliedschaft ist aufrecht | Z23: 21.11.1940 | AE23: postalisch | AF23: postalisch | AG23: Privatadresse | AH23: Carnerigasse 9 | AI23: 8010 | AJ23: Graz | AM23: ÖSTERREICH | AN23: STMK | AQ23: Telefon privat:+43 316 672689 | AR23: felix.feldbacher@gmx.at | AT23: Öffentlicher Dienst - Schulen - Berufsbild. (mittlere u.) höhere Schulen-Pensionist/im Ruhestand - Lehrer/Prof. (Uni. und/oder Schule)-HTBLA-Graz (Ortweinschule) | Freie Berufe - Zivilingenieur-Pensionist/im Ruhestand-Ing. Konsulent f. Vermessungswesen | AU23: Alb Dr. cerevisiae (27.10.2011) | AX23: Alb v. Dr. cer. Tangens (UP:29.5.1961)
A24: 10500275 | C24: Herrn | E24: Dipl.-Ing. | G24: Gabriel | K24: Ferdigg | O24: Scusi | Q24: Lukas Pöcheim v. Knedl | R24: Alb | S24: BU | T24: 06.03.2015 | U24: 21.11.2015 | V24: 29.04.2016 | Y24: Mitgliedschaft ist aufrecht | Z24: 14.12.1992 | AA24: Bruneck | AE24: elektronisch | AF24: postalisch | AG24: Privatadresse | AH24: Neuholdaugasse 36/6 | AI24: 8010 | AJ24: Graz | AM24: ÖSTERREICH | AN24: STMK | AO24: +43 677 62579506 | AR24: gabso92@yahoo.de | AS24: - 2025 Technische Chemie (TU Graz) | 2014 - Umwelt- und Systemwissenschaften - Umwelt- und Systemwissenschaften (Uni Graz) | AV24: Alb:Kassier (SS 2016) | Alb:Kassier (WS 2016/17) | Alb:Kassier (WS 2017/18) | Alb:Fuchsmajor (WS 2018/19) | GCV:OV-Vizepräsident (Von 01. Jul. 2019 bis 30. Jun. 2020) | Alb:Kassier (SS 2026) | AW24: Alb:Kassier (SS 2026) | AX24: Alb v. Scusi (BU:6.3.2015)
A25: 10500037 | C25: Herrn | E25: Dipl.-Ing. Dr. | G25: Martin | K25: Fimberger | N25: B.Sc. | O25: Freibier | Q25: Ronald Weiss v. Ikarus | R25: Alb | S25: UP | T25: 04.12.1991 | U25: Mai 1992 | V25: 14.10.1992 | W25: 28.06.2011 | Y25: Mitgliedschaft ist aufrecht | Z25: 09.04.1973 | AE25: beides | AF25: postalisch | AG25: Privatadresse | AH25: Gmeinstrasse 12d | AI25: 8055 | AJ25: Graz | AM25: ÖSTERREICH | AN25: STMK | AO25: +43 664 4308237 | AQ25: --- falsch ---:+43 664 4308237 | AR25: freibier@albertina-graz.at | AS25: 1991 - Technische Chemie - keine Angabe (TU Graz) | 2012 - 2015 Doktorratsstudium der Technik - Chemie (TU Graz) | AT25: Privatwirtschaft - Industrie - Chemie, Kunststoffe und Pharma-Angestellter - Wissenschaftlicher Mitarbeiter - Forschung, Entwicklung & Wissenschaft-Researcher - Polymerchemie | Privatwirtschaft - Industrie - Elektro, Elektronik und IT-Angestellter - Gruppenleiter - Prozessmanagement-Manager Metrology Engineering | AU25: Alb Dank-Band | Alb 50-Semester Jubelband (29.10.2016) | AV25: Alb:Kassier (WS 1992/93) | Alb:Senior (WS 1993/94) | Alb:Senior (WS 1996/97) | Alb:Fuchsmajor (WS 1997/98) | Alb:Consenior (SS 2002) | Alb:Schriftführer (WS 2002/03) | Alb:Philisterschriftführer (Von 24. Okt. 2015 bis 04. Nov. 2025) | Alb:Philisterschriftführer (Ab 05. Nov. 2025) | AW25: Alb:Philisterschriftführer (Ab 05. Nov. 2025) | AX25: Alb v. Freibier (UP:4.12.1991), BbG v. Freibier (BP:28.6.1996) | AY25: ASG v. Freibier (EP:_.5.2002) | BA25: ASG v. Freibier (EP:_.5.2002)
A26: 11100985 | B26: 985 | C26: Hochwürdiger Herr | D26: Pfr. P. | E26: Mag. | G26: Wolfgang | K26: Fischer-Felgitsch | M26: OSB | O26: Förster vom Silberwald | P26: 31.03.1971: Priesterweihe am 17.06.2006 in der Benediktinerabtei Admont | | Q26: Jürgen Fortin v. Genius | R26: BbG | S26: UP | T26: 12.10.1992 | V26: 29.03.1993 | W26: 27.06.2006 | Y26: Mitgliedschaft ist aufrecht | Z26: 31.03.1971 | AA26: Graz | AE26: postalisch | AF26: postalisch | AG26: Privatadresse | AH26: Kirchplatz 1 | AI26: 8911 | AJ26: Admont | AK26: Benediktinerabtei Admont | AM26: ÖSTERREICH | AN26: STMK | AO26: +43 660 1121312 | AQ26: Telefon privat:+43 3613 2312-223 Fax privat:+43 3613 2312-221 | AR26: wolfgang@stiftadmont.at | AS26: 1991 - 2001 Betriebswirtschaft - keine Angabe (Uni Graz) | 2000 - 2006 Fachtheologie (Katholische Theologie) - keine Angabe (Uni Salzburg) | 2002 - 2004 Fachtheologie (Katholische Theologie) - Fachtheologie (Katholische Theologie) (Uni im Ausland) | AT26: Körperschaften/Verbände - Klöster und Stifte - Ordensangehöriger-Priester-Benediktinerabtei Admont | Körperschaften/Verbände - Katholische Kirche - Diözese Graz-Seckau-Pfarrer- | AX26: BbG v. Förster vom Silberwald (UP:12.10.1992), Alb v. Förster vom Silberwald (BP:_._.1997), Lo v. Förster vom Silberwald (BP:8.11.2002) | AY26: WOL v. Förster vom Silberwald (EP:21.10.2000), MEG v. Förster vom Silberwald (EP:_._.2007) | AZ26: Cp v. Förster vom Silberwald (BP:_.10.2002), AlgA v. Förster vom Silberwald (BP:5.11.1993) | BA26: WOL v. Förster vom Silberwald (EP:21.10.2000), MEG v. Förster vom Silberwald (EP:_._.2007)
A27: 10500068 | C27: Herrn | G27: Wolfgang | K27: Friedhuber | O27: Landskrona | Q27: Christian Tauschmann v. Nagelprobe | R27: Alb | S27: BU | T27: 11.10.2008 | U27: 07.12.2009 | V27: 13.03.2010 | Y27: Mitgliedschaft ist aufrecht | Z27: 26.09.1987 | AA27: Graz | AE27: elektronisch | AF27: postalisch | AG27: Privatadresse | AH27: Glacisstraße 61 | AI27: 8010 | AJ27: Graz | AM27: ÖSTERREICH | AN27: STMK | AO27: +43 664 1414012 | AR27: wolfgang.friedhuber@aon.at | AS27: 0 - 0 Mathematik - keine Angabe (TU Graz) | AX27: Alb v. Landskrona (BU:11.10.2008)
A28: 11100445 | B28: 445 | C28: Herrn | D28: Dir. i.R. Komm.R | E28: Dipl.-Ing. | G28: Karl Ernst | K28: Friedl | O28: Dr. cer. Bibi | P28: 01.12.1935: Ehe 09.09.1961 mit Gertraut, geb. Kölli, 3 Kinder: Karl (BbG Carlos) * 1962, Helga * 1964, Herbert (BbG Dschunior) * 1968 | 01.12.1935: Im Organisationsteam der ÖCV-Schimeisterschaften 1964 - 1972 und 1984 - März 2005 | 01.12.1935: 7.Mai 1954 Reception 1954/55 durch seine Initiative gekeilt (alles Schulkollegen): R.Ott v/g Bondi, G.Rauter/Strolch, H.Schuchlenz/Quax, L.Stöckler/Camillo, W.Deu/Bambi | 01.12.1935: Chargen: 1955/56 Consenior Organisation eines Tanzkurses (lernte dort seine spätere Gattin kennen!) Organisation der Babenberg Schitage (St.Ilgen), aus denen sich über die GCV- und dann die ÖCV-Schimeisterschaften (Mäcky, Bondi) entwickelten WS 1959/60 Senior Hauptarbeit: die Vorbereitung auf das 40. Stiftungsfest 1968-1973 Phil-Kassier-2 Anschaffung der neuen Bude Schießstattgasse Vater Phil-Kassier-1: Budenfinanzierung Bibi: "normaler" Verbindungsbetrieb 1991-1996 Phil.Senior (laut Bibi persönlich (2020) sind die Zahlen im Verbindungsbuch sind falsch!) 75. Jahre Babenberg! | 01.12.1935: Schitage: BbG-Schitage St.Ilgen, Leitung Bibi: 1956, 1959, 1963, 1967, 1974 GCV-Schimeisterschaften: 1959, 1962, 1963, 1966, 1967, 1968, 1969, Org-Team: Mäcky, Bondi, Bibi ÖCV-Schimeisterschaften: 49 mal verteilt über Österreich, Leitung Mäcky, dann Bondi, zum Schluss Bobu Bibi im Org-Team: 1964 - 1973 (danach 15 Jahre nicht = Gemeinderat Graz) ab 1987 wieder im Org-Team | 01.12.1935: Jubelbänder: BbG.: 1979 50 Sem. / 1991 75 Sem. / 2004 100 Sem. / 2016 125 Semester-Jubelband Alb.: 2001 50 Sem. | 01.12.1935: Ehrungen: xx.xx.1982 Gold. EZ Steirischer Wirtschaftsbund 21.01.1983 Sport-EZ der Landeshauptstadt Graz 21.11.1994 Landes-Sport EZ Steiermark 07.11.1995 Gold. EZ der österr. Sportunion 19.11.1998 Verleihung des Titels Kommerzialrat 21.05.2015 Goldenes Diplom der Technischen Universität Graz (gemeins mit Bbr. Haberfellner/Schluck und Bbr. Wronski/Würstl) 06.11.2019 Verleihung des Großen Ehrenzeichen des Landes Steiermark (Silberner EZ -> Goldenes EZ -> Großes EZ) | 01.12.1935: 7.Mai 1954 Rezeption (Vor der Matura!, endlich wieder junge Fuxen in die Verbindung zu bringen (über mein Betreiben wurden 1954/55 recipiert:: R.Ott v/g Bondi, G.Rauter/Strolch, H.Schuchlenz/Quax, L.Stöckler/Camillo, W.Deu/Bambi, alles Schulkollegen). WS 1955/56 Consenier, Es gab wieder gut besuchte Veranstaltungen, Tanzkurs, (dort lernte ich meine spätere Gattin kennen) und die Babenberg Schitage (St.Ilgen) aus denen sich über die GCV- und dann die ÖCV-Schimeisterschaften(Mäcky, Bondi) entwickelten, sind hervorzuheben. BbG-Schitage St.Ilgen, Leitung Bibi: 1956, 1959, 1963, 1967, 1974; GCV-Schimeisterschaften: 1959, 1962, 1963, 1966, 1967, 1968, 1969, Mäcky, Bondi, Bibi im Org-Team ÖCV-Schimeisterschaften: 49 mal verteilt über Österreich,Leitung Mäcky, dann Bondi, zum Schluss Bobu, Bibi im Org-Team: 1964 - 1973 (danach 15 Jahre nicht = Gemeinderat Graz) ab 1987 wieder im Org.Team. WS 1959/60 Senior; Hauptarbeit: die Vorbereitung auf das 40. Stiftungsfest. 1968-1973 Phil-Kassier-2, in diese Zeit fiel die Anschaffung der Neuen Bude Schießstattgasse, wobei mein Vater die Budenfinanzierung übernahm und ich den "normalen" Verbindungsbetrieb zu betreuen hatte. 27.10.1976 wurde mir, anlässlich des 15. Stiftungsfestes, das Band e.v. KÖAV Albertina verliehen. 10.10.1981 wurde mir die Ehrenmitgliedschaft einer e.v. Laurinia zu Graz im MKV übertragen. 1991-1996 Phil.Senior (die Zahlen im Verbindungsbuch sind leider falsch) In diese Zeit fiel unser Jubiläum 75. Jahre Babenberg-Graz, dieses prägte das ganze Sommersemester.. 20.3.1998 wurde mir, gemeinsam mit Bbr. Bondi und Bbr. Struppi die höchste Auszeichnung der Verbindung, der Titel Dr.cer. verliehen. Jubelbänder: BbG.: 1979 50 Sem. / 1991 75 Sem / 2004 100Sem. / 2016 125 Semester-Jubelband Alb.: 2001 50 Sem. Ehrungen: 1982 Gold. EZ Steirischer Wirtschaftsbund 21.01.1983 Sport-EZ der Landeshauptstadt Graz 21.11.1994 Landes-Sport EZ Steiermark 07.11.1995 Gold. EZ der österr. Sportunion 19.11.1998 Verleihung des Titels Kommerzialrat 21.05.2015 Goldenes Diplom der Technischen Universität Graz, gemeins mit Bbr Hberfellner/Schluck und Bbr. Wronski/ Würstl 06.11.2019 Verleihung des Großen Ehrenzeichen des Landes Steiermark (Silb.EZ; -> Gld, EZ -> Großes EZ --> ) | | Q28: Georg Günther Schäffer (†) v. Kadi | R28: BbG | S28: UP | T28: 07.05.1954 | V28: 25.05.1955 | W28: Nov. 1965 | Y28: Mitgliedschaft ist aufrecht | Z28: 01.12.1935 | AA28: Graz | AE28: postalisch | AF28: postalisch | AG28: Privatadresse | AH28: Wetzelsdorfer Straße 151 | AI28: 8052 | AJ28: Graz | AM28: ÖSTERREICH | AN28: STMK | AO28: +43 664 2220602 | AQ28: Telefon privat:+43 316 572813 Fax privat:+43 316 572813 | AR28: ke.friedl@gmx.at | AS28: 1954 - Wirtschaftsingenieurwesen - Bauwesen - keine Angabe (TU Graz) | AT28: Öffentliche Wirtschaft - Energieversorgung-Pensionist/im Ruhestand - Mitgl. d. Vorst., Geschäftsl. oder Direktion- | AU28: BbG Dr. cerevisiae (20.03.1998) | Alb 50-Semester Jubelband (27.10.2001) | BbG 100-Semester Jubelband (12.06.2004) | BbG 125-Semester Jubelband (28.05.2016) | Alb 100-Semester Jubelband (14.03.2020) | AV28: BbG:Consenior (Von 15. Sep. 1955 bis 15. Feb. 1956) | BbG:Senior (Von 15. Sep. 1959 bis 15. Feb. 1960) | BbG:Philisterkassier (Von 01. Jan. 1968 bis 31. Dez. 1973) | BbG:Philistersenior (Von 01. Jan. 1991 bis 31. Dez. 1996) | AX28: BbG v. Dr. cer. Bibi (UP:7.5.1954), Alb v. Bibi (EP:27.10.1976) | AY28: LRG v. Bibi (EP:10.10.1981) | BA28: LRG v. Bibi (EP:10.10.1981)
A29: 10500278 | C29: Herrn | G29: Jochen | K29: Friedrich | O29: Geschwisterliebe | Q29: Johannes Zeiringer v. Hephaistos | R29: Alb | S29: BU | T29: 29.01.2016 | U29: 02.12.2016 | V29: 03.02.2017 | Y29: Mitgliedschaft ist aufrecht | Z29: 03.12.1995 | AA29: Mödling | AE29: elektronisch | AF29: postalisch | AG29: Privatadresse | AH29: Wallerweg 1 | AI29: 9201 | AJ29: Krumpendorf | AM29: ÖSTERREICH | AN29: K | AO29: +43 680 1152956 | AR29: jochen.danielfr@gmail.com | AS29: 2015 - Philosophie, Pädagogik und Psychologie (Lehramt) (Uni Graz) | 2015 - Geschichte Studienzweig: Geschichte und Sozialkunde (Lehramt) (Uni Graz) | AV29: Alb:Barwart (WS 2016/17) | Alb:Consenior (SS 2017) | AX29: Alb v. Geschwisterliebe (BU:29.1.2016) | AY29: GLK v. Straganz (BU:26.4.2013) | BA29: GLK v. Straganz (BU:26.4.2013)
A30: 10500288 | C30: Herrn | G30: Lukas | K30: Frießnegger | O30: Helmi | Q30: Oliver Korak v. Hodor | R30: Alb | S30: BU | T30: 29.10.2017 | U30: 01.02.2019 | V30: 07.03.2020 | Y30: Mitgliedschaft ist aufrecht | Z30: 10.02.1997 | AA30: Klagenfurt | AE30: elektronisch | AF30: postalisch | AG30: Privatadresse | AH30: Plüddemanngasse 56 | AI30: 8010 | AJ30: Graz | AM30: ÖSTERREICH | AN30: STMK | AO30: +43 676 83555825 | AR30: lukas.friessnegger@gmx.at | AS30: 2018 - Telematik - keine Angabe (TU Graz) | AV30: Alb:Barwart (SS 2019) | Alb:Fuchsmajor (WS 2021/22) | Alb:Senior (SS 2022) | Alb:Standesführer ÖCV.Net (Ab 22. Jun. 2023) | Alb:IT-Beauftragter (Ab 01. Jul. 2023) | Alb:Senior (SS 2024) | GCV:OV-Präsident (Von 24. Jan. 2025 bis 30. Jun. 2025) | Alb:Consenior 1 (WS 2025/26) | Alb:Senior (SS 2026) | AW30: Alb:Standesführer ÖCV.Net (Ab 22. Jun. 2023) | Alb:IT-Beauftragter (Ab 01. Jul. 2023) | Alb:Senior (SS 2026) | AX30: Alb v. Helmi (BU:29.10.2017) | AY30: BBK v. Helmi (UP:), MEG v. Helmi (BP:), PLP v. Helmi (BP:) | BA30: BBK v. Helmi (UP:), MEG v. Helmi (BP:), PLP v. Helmi (BP:)
A31: 10500103 | C31: Herrn | D31: Prof. | E31: Dipl.-Ing. | G31: Erhard | K31: Glauninger | O31: Pollux | R31: Alb | S31: UP | T31: 26.06.1961 | V31: 07.06.1962 | Y31: Mitgliedschaft ist aufrecht | Z31: 07.10.1938 | AE31: postalisch | AF31: postalisch | AG31: Privatadresse | AH31: Leitnerberg 9 | AI31: 4490 | AJ31: St. Florian | AM31: ÖSTERREICH | AN31: OÖ | AO31: +43 664 3843505 | AQ31: Telefon privat:+43 7224 8032 | AR31: eg_@gmx.at | AT31: Öffentlicher Dienst - Schulen - Allgemeinbildende höhere Schulen-Pensionist/im Ruhestand - Lehrer/Prof. (Uni. und/oder Schule)- | AX31: Alb v. Pollux (UP:26.6.1961)
A32: 10500277 | C32: Herrn | G32: Fabian | K32: Gollmann | O32: Promilltheus | Q32: Peter Hinteregger-Frießnegger v. Remus | R32: Alb | S32: BU | T32: 24.10.2015 | U32: 02.12.2016 | V32: 03.02.2017 | Y32: Mitgliedschaft ist aufrecht | Z32: 13.08.1995 | AA32: Klagenfurt | AE32: elektronisch | AF32: postalisch | AG32: Studienadresse | AH32: Plüddemanngasse 56/6 | AI32: 8010 | AJ32: Graz | AM32: ÖSTERREICH | AN32: STMK | AO32: +43 664 8780779 | AR32: gollmann@gmx.net | AS32: 2015 - Elektrotechnik (TU Graz) | AV32: Alb:Consenior 1 (WS 2017/18) | Alb:Consenior (SS 2018) | AX32: Alb v. Promilltheus (BU:24.10.2015) | AY32: BBK v. Prometheus (BU:1.1.2011) | BA32: BBK v. Prometheus (BU:1.1.2011)
A33: 10500070 | C33: Herrn | E33: Ing. Dipl.-Wirtschaftsing. (FH) | G33: Christian | K33: Gorsche | O33: Loki II | Q33: Christian Tauschmann v. Nagelprobe | R33: Alb | S33: UP | T33: 03.10.2008 | U33: 15.05.2009 | V33: 26.06.2009 | W33: 17.10.2020 | Y33: Mitgliedschaft ist aufrecht | Z33: 24.02.1980 | AA33: Graz | AE33: postalisch | AF33: postalisch | AG33: Privatadresse | AH33: Markt 181/2 | AI33: 8323 | AJ33: Sankt Marein bei Graz-Markt | AM33: ÖSTERREICH | AN33: STMK | AO33: +43 660 8139393 | AR33: christian.gorsche@gmail.com | AS33: 0 - 0 Politikwissenschaft - Politikwissenschaft (Uni im Ausland) | AV33: Alb:Consenior (WS 2009/10) | AX33: Alb v. Loki II (UP:3.10.2008) | AY33: ASG v. Loki (UP:22.3.2013) | BA33: ASG v. Loki (UP:22.3.2013)
A34: 10500286 | C34: Herrn | E34: Dipl.-Ing. | G34: Maximilian | K34: Grillitsch | N34: BSc | O34: Baking Bread | Q34: Jakob Rautz v. Wikipedia | R34: Alb | S34: UP | T34: 29.04.2017 | U34: 15.12.2017 | V34: 04.05.2018 | W34: 26.10.2024 | Y34: Mitgliedschaft ist aufrecht | Z34: 30.10.1996 | AA34: Wolfsberg | AE34: elektronisch | AF34: postalisch | AG34: Privatadresse | AH34: Strauchergasse 13/20 | AI34: 8020 | AJ34: Graz | AM34: ÖSTERREICH | AN34: STMK | AO34: +43 699 15095646 | AR34: maximilian.g@outlook.com | AS34: 2016 - 2020 Physik - keine Angabe (TU Graz) | 2020 - 2023 Materialwissenschaft (TU Graz) | AV34: Alb:Barwart (SS 2018) | Alb:Consenior (WS 2018/19) | Alb:Consenior (WS 2019/20) | Alb:Consenior 1 (WS 2021/22) | Alb:Kassier (SS 2022) | Alb:Senior (WS 2022/23) | Alb:Schriftführer (WS 2025/26) | Alb:Schriftführer (SS 2026) | AW34: Alb:Schriftführer (SS 2026) | AX34: Alb v. Baking Bread (UP:29.4.2017)
A35: 10500282 | C35: Herrn | G35: Christian | K35: Groß-Edelsbrunner | O35: Stölzn | Q35: Oliver Korak v. Hodor | R35: Alb | S35: UP | T35: 30.09.2016 | U35: 03.02.2017 | V35: 04.05.2018 | W35: 06.12.2025 | Y35: Mitgliedschaft ist aufrecht | Z35: 11.04.1997 | AA35: Wolfsberg | AE35: elektronisch | AF35: postalisch | AG35: Privatadresse | AH35: Jakob-Redtenbacher-Gasse 28/3 | AI35: 8010 | AJ35: Graz | AM35: ÖSTERREICH | AN35: STMK | AO35: +43 660 2645460 | AR35: grosz.c.b@gmail.com | AS35: 2016 - Mathematik (TU Graz) | 2020 - Psychologie (Uni Graz) | AV35: Alb:Senior (WS 2018/19) | Alb:Fuchsmajor (SS 2019) | Alb:IT-Beauftragter (Von 01. Jul. 2023 bis 29. Sep. 2025) | AX35: Alb v. Stölzn (UP:30.9.2016) | AY35: PLP v. Klein (UP:23.6.2012) | BA35: PLP v. Klein (UP:23.6.2012)
A36: 10500095 | C36: Herrn | G36: Gabriel | K36: Gruber | O36: Falco | Q36: Michael Maier v. Limbo | R36: Alb | S36: UP | T36: 03.06.2011 | U36: 28.01.2012 | V36: 11.05.2012 | W36: 29.01.2025 | Y36: Mitgliedschaft ist aufrecht | Z36: 14.11.1986 | AA36: Wels | AE36: elektronisch | AF36: postalisch | AG36: Privatadresse | AH36: Stockheimweg 11 | AI36: 8164 | AJ36: Gutenberg | AM36: ÖSTERREICH | AN36: STMK | AO36: +43 650 6016064 | AR36: gabriel.gruber@icloud.com | AS36: - Softwareentwicklung - Wirtschaft - Softwareentwicklung - Wirtschaft (TU Graz) | AV36: Alb:Chefredakteur (Von 01. Mrz. 2012 bis 01. Jul. 2013) | Alb:Consenior 1 (WS 2012/13) | Alb:Consenior (SS 2013) | AX36: Alb v. Falco (UP:3.6.2011)
A37: 10500104 | C37: Herrn | E37: DDipl.-Ing. | G37: Horst | K37: Gruber | O37: Dr. cer. Kastor | R37: Alb | S37: UP | T37: 26.06.1961 | V37: 07.06.1962 | Y37: Mitgliedschaft ist aufrecht | Z37: 01.01.1940 | AE37: postalisch | AF37: postalisch | AG37: Privat- & Berufsadresse | AH37: Am Schloßhang 1 | AI37: 8075 | AJ37: Hart bei Graz | AM37: ÖSTERREICH | AN37: STMK | AQ37: Telefon privat:+43 316 491401 | AR37: gruber.ho@gmail.com | AS37: 0 - 0 Wirtschaftsingenieurwesen - Maschinenbau - keine Angabe (TU Graz) | AT37: Freie Berufe - Psychotherapeut-Freiberufler - Unternehmensberatung- | Freie Berufe - Psychotherapeut-Selbständiger- | AU37: Alb Dank-Band | Alb Dr. cerevisiae (27.10.2011) | AX37: Alb v. Dr. cer. Kastor (UP:26.6.1961)
A38: 10500222 | C38: Herrn | E38: Dr. | G38: Bernhard | K38: Gutschreiter | O38: Fliege | Q38: Peter Pfaffenwimmer v. Schilcher | R38: Alb | S38: UP | T38: 10.10.1994 | V38: 1996 | W38: 26.10.2000 | Y38: Mitgliedschaft ist aufrecht | Z38: 12.06.1973 | AE38: postalisch | AF38: postalisch | AG38: Privatadresse | AH38: Weinheberstraße 6 | AI38: 4050 | AJ38: Sankt Martin | AM38: ÖSTERREICH | AN38: OÖ | AO38: +43 664 9215001 | AQ38: Telefon privat:+43 3842 22279 | AR38: gutschreiter@hotmail.com | AS38: - Medizin - keine Angabe (Uni Graz) | AT38: Körperschaften/Verbände-Angestellter - Assistenzarzt-Konventhospital der Barmherzigen Brüder Linz | AX38: Alb v. Fliege (UP:10.10.1994)
A39: 10500011 | C39: Herrn | D39: RA | E39: Mag. | G39: Maximilian | K39: Gutschreiter | O39: Hägar | R39: Alb | S39: UP | T39: 29.11.1988 | U39: 1989 | V39: 15.12.1989 | W39: 1996 | Y39: Mitgliedschaft ist aufrecht | Z39: 08.07.1968 | AE39: postalisch | AF39: postalisch | AG39: Privatadresse | AH39: Kienbergweg 12 | AI39: 8700 | AJ39: Leoben | AM39: ÖSTERREICH | AN39: STMK | AO39: +43 676 3303842 | AQ39: Telefon dienstlich:+43 3842 42100 Fax dienstlich:+43 3842 42100-10 Telefon privat:+43 3842 22235 | AR39: kanzlei@ra-gutschreiter.at | AS39: 1988 - Rechtswissenschaften - keine Angabe (Uni Graz) | AT39: Freie Berufe - Rechtsanwalt-Angestellter- | AV39: Alb:Vorsitzender des Verbindungsgerichtes (Bis 01. Okt. 2017) | AX39: Alb v. Hägar (UP:29.11.1988) | AY39: LUL v. Hägar (UP:_._.1985) | BA39: LUL v. Hägar (UP:_._.1985)
A40: 13900164 | C40: Herrn | D40: OR | E40: Dipl.-Ing. | G40: Friedrich | K40: Hartl | O40: Pippin | Q40: Roland Dünser v. Clochard | R40: Trn | S40: UP | T40: 13.12.1969 | U40: 05.12.1970 | V40: 06.02.1971 | W40: 10.06.1977 | Y40: Mitgliedschaft ist aufrecht | Z40: 05.11.1948 | AE40: postalisch | AF40: postalisch | AG40: Privatadresse | AH40: Moosstraße 107 C | AI40: 5020 | AJ40: Salzburg | AM40: ÖSTERREICH | AN40: S | AQ40: Telefon privat:+43 662 828248 | AS40: 1969 - keine Angabe - keine Angabe (TU Graz) | AT40: Öffentlicher Dienst - Bundesverwaltung - BM für Soziales, Gesundheit und Pflege-Pensionist/im Ruhestand-Arbeitsinspektorat Salzburg | AX40: Trn v. Pippin (UP:13.12.1969), Alb v. Pippin (BP:_._.1973)
A41: 10500106 | C41: Herrn | D41: Med.R | E41: Dr. | G41: Franz | K41: Hasengschwandtner | O41: Rübezahl | P41: 06.12.1946: Präsident Network Global Health | www.network-globalhealth.com | 06.12.1946: ärztl. Leiter Netzwerk Lipolyse | www.netzwerk-lipolyse.de | 06.12.1946: Medizinisches Engagement in Nicaragua | 06.12.1946: Costa Rica | Klinikprojekt und Projekt Regenwalt der Österreicher | 06.12.1946: Reiseclub "Papa Doc" | 06.12.1946: Rheuma Selbsthilfegruppen | | R41: Alb | S41: UP | T41: 11.11.1964 | V41: 22.11.1965 | Y41: Mitgliedschaft ist aufrecht | Z41: 06.12.1946 | AE41: postalisch | AF41: postalisch | AG41: Privatadresse | AH41: Köckendorf 76 | AI41: 4184 | AJ41: Köckendorf | AM41: ÖSTERREICH | AN41: OÖ | AO41: +43 664 73517814 | AR41: franzhasengschwandtner@gmail.com | AS41: 1964 - Medizin - keine Angabe (Uni Graz) | AT41: Freie Berufe - Arzt - Praktischer Arzt (Allgemeinmed.)-Selbständiger - Freiberufler - Bereichsleitung- | AV41: GCV:OV-Präsident (Von 01. Jul. 1968 bis 30. Jun. 1969) | AX41: Alb v. Rübezahl (UP:11.11.1964) | AY41: FRV v. Rübezahl (UP:_._.1960) | BA41: FRV v. Rübezahl (UP:_._.1960)
...

Sheet Mailingdaten
A5: CbrPoint | B5: LaufendeNummer | C5: Vorname | D5: Nachname | E5: Couleurname | F5: E-Mail
A6: =IF(Exportdaten!A6<>"",Exportdaten!A6,"") -> 10500102 | B6: =IF(Exportdaten!B6<>"",Exportdaten!B6,"") | C6: =IF(Exportdaten!G6<>"",Exportdaten!G6,"") -> Maximilian | D6: =IF(Exportdaten!K6<>"",Exportdaten!K6,"") -> Amort | E6: =IF(Exportdaten!O6<>"",Exportdaten!O6,"") -> Stoiber | F6: =IF(Exportdaten!AR6<>"",Exportdaten!AR6,"") -> maximilian.amort@gmail.com
A7: =IF(Exportdaten!A7<>"",Exportdaten!A7,"") -> 10500150 | B7: =IF(Exportdaten!B7<>"",Exportdaten!B7,"") | C7: =IF(Exportdaten!G7<>"",Exportdaten!G7,"") -> Engelbert | D7: =IF(Exportdaten!K7<>"",Exportdaten!K7,"") -> Aspeck | E7: =IF(Exportdaten!O7<>"",Exportdaten!O7,"") -> Paracelsus | F7: =IF(Exportdaten!AR7<>"",Exportdaten!AR7,"") -> engelbert.aspeck@outlook.com
A8: =IF(Exportdaten!A8<>"",Exportdaten!A8,"") -> 10500310 | B8: =IF(Exportdaten!B8<>"",Exportdaten!B8,"") | C8: =IF(Exportdaten!G8<>"",Exportdaten!G8,"") -> Gerald | D8: =IF(Exportdaten!K8<>"",Exportdaten!K8,"") -> Baumschlager | E8: =IF(Exportdaten!O8<>"",Exportdaten!O8,"") -> HalloElke | F8: =IF(Exportdaten!AR8<>"",Exportdaten!AR8,"") -> gerald.baumschlager@gmail.com
A9: =IF(Exportdaten!A9<>"",Exportdaten!A9,"") -> 10500298 | B9: =IF(Exportdaten!B9<>"",Exportdaten!B9,"") | C9: =IF(Exportdaten!G9<>"",Exportdaten!G9,"") -> Matthias | D9: =IF(Exportdaten!K9<>"",Exportdaten!K9,"") -> Berger | E9: =IF(Exportdaten!O9<>"",Exportdaten!O9,"") -> HengtBoss | F9: =IF(Exportdaten!AR9<>"",Exportdaten!AR9,"") -> bergermatthias95@gmail.com
A10: =IF(Exportdaten!A10<>"",Exportdaten!A10,"") -> 10500022 | B10: =IF(Exportdaten!B10<>"",Exportdaten!B10,"") | C10: =IF(Exportdaten!G10<>"",Exportdaten!G10,"") -> David | D10: =IF(Exportdaten!K10<>"",Exportdaten!K10,"") -> Binder | E10: =IF(Exportdaten!O10<>"",Exportdaten!O10,"") -> Kojak II. | F10: =IF(Exportdaten!AR10<>"",Exportdaten!AR10,"") -> david.binder@gmx.at
A11: =IF(Exportdaten!A11<>"",Exportdaten!A11,"") -> 13101359 | B11: =IF(Exportdaten!B11<>"",Exportdaten!B11,"") | C11: =IF(Exportdaten!G11<>"",Exportdaten!G11,"") -> Stefan | D11: =IF(Exportdaten!K11<>"",Exportdaten!K11,"") -> Blümke | E11: =IF(Exportdaten!O11<>"",Exportdaten!O11,"") -> Pizzi | F11: =IF(Exportdaten!AR11<>"",Exportdaten!AR11,"") -> bluemke@bssk.at
A12: =IF(Exportdaten!A12<>"",Exportdaten!A12,"") -> 10500121 | B12: =IF(Exportdaten!B12<>"",Exportdaten!B12,"") | C12: =IF(Exportdaten!G12<>"",Exportdaten!G12,"") -> Reinhold | D12: =IF(Exportdaten!K12<>"",Exportdaten!K12,"") -> Böhler | E12: =IF(Exportdaten!O12<>"",Exportdaten!O12,"") -> Cid | F12: =IF(Exportdaten!AR12<>"",Exportdaten!AR12,"") -> boehler.reinhold@gmail.com
A13: =IF(Exportdaten!A13<>"",Exportdaten!A13,"") -> 10500100 | B13: =IF(Exportdaten!B13<>"",Exportdaten!B13,"") | C13: =IF(Exportdaten!G13<>"",Exportdaten!G13,"") -> Gebhard | D13: =IF(Exportdaten!K13<>"",Exportdaten!K13,"") -> Brandweiner | E13: =IF(Exportdaten!O13<>"",Exportdaten!O13,"") -> SichaNet | F13: =IF(Exportdaten!AR13<>"",Exportdaten!AR13,"") -> sichanet@albertina-graz.at
A14: =IF(Exportdaten!A14<>"",Exportdaten!A14,"") -> 11100786 | B14: =IF(Exportdaten!B14<>"",Exportdaten!B14,"") -> 786 | C14: =IF(Exportdaten!G14<>"",Exportdaten!G14,"") -> Gernot | D14: =IF(Exportdaten!K14<>"",Exportdaten!K14,"") -> Brandweiner | E14: =IF(Exportdaten!O14<>"",Exportdaten!O14,"") -> Stiel | F14: =IF(Exportdaten!AR14<>"",Exportdaten!AR14,"") -> brandweiner_gernot@outlook.com
A15: =IF(Exportdaten!A15<>"",Exportdaten!A15,"") -> 10500044 | B15: =IF(Exportdaten!B15<>"",Exportdaten!B15,"") | C15: =IF(Exportdaten!G15<>"",Exportdaten!G15,"") -> Viktor | D15: =IF(Exportdaten!K15<>"",Exportdaten!K15,"") -> Brudniak | E15: =IF(Exportdaten!O15<>"",Exportdaten!O15,"") -> Ex | F15: =IF(Exportdaten!AR15<>"",Exportdaten!AR15,"") -> viktor.brudniak@gmx.at
A16: =IF(Exportdaten!A16<>"",Exportdaten!A16,"") -> 10500229 | B16: =IF(Exportdaten!B16<>"",Exportdaten!B16,"") | C16: =IF(Exportdaten!G16<>"",Exportdaten!G16,"") -> Lukas | D16: =IF(Exportdaten!K16<>"",Exportdaten!K16,"") -> Charisius | E16: =IF(Exportdaten!O16<>"",Exportdaten!O16,"") -> Enrico | F16: =IF(Exportdaten!AR16<>"",Exportdaten!AR16,"") -> lukas.charisius@jus.cc
A17: =IF(Exportdaten!A17<>"",Exportdaten!A17,"") -> 12200062 | B17: =IF(Exportdaten!B17<>"",Exportdaten!B17,"") | C17: =IF(Exportdaten!G17<>"",Exportdaten!G17,"") -> Markus | D17: =IF(Exportdaten!K17<>"",Exportdaten!K17,"") -> Charisius | E17: =IF(Exportdaten!O17<>"",Exportdaten!O17,"") -> Merlin | F17: =IF(Exportdaten!AR17<>"",Exportdaten!AR17,"") -> markus.charisius@gmail.com
... A173: =IF(Exportdaten!A173<>"",Exportdaten!A173,"") -> 10500096 | B173: =IF(Exportdaten!B173<>"",Exportdaten!B173,"") | C173: =IF(Exportdaten!G173<>"",Exportdaten!G173,"") -> Nikolaus | D173: =IF(Exportdaten!K173<>"",Exportdaten!K173,"") -> Zoltan | E173: =IF(Exportdaten!O173<>"",Exportdaten!O173,"") -> Flipper | F173: =IF(Exportdaten!AR173<>"",Exportdaten!AR173,"") -> zoltan.niko@gmail.com

Sheet Adressdaten
P3: Zustelladresse
A5: CbrPoint | B5: LaufendeNummer | C5: Anrede | D5: Berufstitel | E5: AkademischerGrad | F5: VornamePrae | G5: Vorname | H5: Vorname2 | I5: VornamePost | J5: NachnamePrae | K5: Nachname | L5: NachnamePost | M5: Orden | N5: PostgradualerTitel | O5: Verbindungszeitung | P5: Adresstyp | Q5: Strasse | R5: PLZ | S5: Ort | T5: co1 | U5: co2 | V5: Land
A6: =IF(Exportdaten!A6<>"",Exportdaten!A6,"") -> 10500102 | B6: =IF(Exportdaten!B6<>"",Exportdaten!B6,"") | C6: =IF(Exportdaten!C6<>"",Exportdaten!C6,"") -> Herrn | D6: =IF(Exportdaten!D6<>"",Exportdaten!D6,"") | E6: =IF(Exportdaten!E6<>"",Exportdaten!E6,"") | F6: =IF(Exportdaten!F6<>"",Exportdaten!F6,"") | G6: =IF(Exportdaten!G6<>"",Exportdaten!G6,"") -> Maximilian | H6: =IF(Exportdaten!H6<>"",Exportdaten!H6,"") -> Joseph Andreas | ... N6: =IF(Exportdaten!N6<>"",Exportdaten!N6,"") | O6: =IF(Exportdaten!AF6<>"",Exportdaten!AF6,"") -> postalisch | P6: =IF(Exportdaten!AG6<>"",Exportdaten!AG6,"") -> Privatadresse | Q6: =IF(Exportdaten!AH6<>"",Exportdaten!AH6,"") -> 38, rue de la Corniche | R6: =IF(Exportdaten!AI6<>"",Exportdaten!AI6,"") -> 5956 | S6: =IF(Exportdaten!AJ6<>"",Exportdaten!AJ6,"") -> Itzig | T6: =IF(Exportdaten!AK6<>"",Exportdaten!AK6,"") | U6: =IF(Exportdaten!AL6<>"",Exportdaten!AL6,"") | V6: =IF(Exportdaten!AM6<>"",Exportdaten!AM6,"") -> LUXEMBURG
A7: =IF(Exportdaten!A7<>"",Exportdaten!A7,"") -> 10500150 | B7: =IF(Exportdaten!B7<>"",Exportdaten!B7,"") | C7: =IF(Exportdaten!C7<>"",Exportdaten!C7,"") -> Herrn | D7: =IF(Exportdaten!D7<>"",Exportdaten!D7,"") | E7: =IF(Exportdaten!E7<>"",Exportdaten!E7,"") -> Dr. | F7: =IF(Exportdaten!F7<>"",Exportdaten!F7,"") | G7: =IF(Exportdaten!G7<>"",Exportdaten!G7,"") -> Engelbert | H7: =IF(Exportdaten!H7<>"",Exportdaten!H7,"") | ... N7: =IF(Exportdaten!N7<>"",Exportdaten!N7,"") | O7: =IF(Exportdaten!AF7<>"",Exportdaten!AF7,"") -> postalisch | P7: =IF(Exportdaten!AG7<>"",Exportdaten!AG7,"") -> Privatadresse | Q7: =IF(Exportdaten!AH7<>"",Exportdaten!AH7,"") -> Unterer Plattenweg 65 | R7: =IF(Exportdaten!AI7<>"",Exportdaten!AI7,"") -> 8043 | S7: =IF(Exportdaten!AJ7<>"",Exportdaten!AJ7,"") -> Graz | T7: =IF(Exportdaten!AK7<>"",Exportdaten!AK7,"") | U7: =IF(Exportdaten!AL7<>"",Exportdaten!AL7,"") | V7: =IF(Exportdaten!AM7<>"",Exportdaten!AM7,"") -> ÖSTERREICH
A8: =IF(Exportdaten!A8<>"",Exportdaten!A8,"") -> 10500310 | B8: =IF(Exportdaten!B8<>"",Exportdaten!B8,"") | C8: =IF(Exportdaten!C8<>"",Exportdaten!C8,"") -> Herrn | D8: =IF(Exportdaten!D8<>"",Exportdaten!D8,"") | E8: =IF(Exportdaten!E8<>"",Exportdaten!E8,"") | F8: =IF(Exportdaten!F8<>"",Exportdaten!F8,"") | G8: =IF(Exportdaten!G8<>"",Exportdaten!G8,"") -> Gerald | H8: =IF(Exportdaten!H8<>"",Exportdaten!H8,"") | ... N8: =IF(Exportdaten!N8<>"",Exportdaten!N8,"") -> BSc | O8: =IF(Exportdaten!AF8<>"",Exportdaten!AF8,"") -> postalisch | P8: =IF(Exportdaten!AG8<>"",Exportdaten!AG8,"") -> Privatadresse | Q8: =IF(Exportdaten!AH8<>"",Exportdaten!AH8,"") -> Kettengasse 3b / 14 | R8: =IF(Exportdaten!AI8<>"",Exportdaten!AI8,"") -> 8010 | S8: =IF(Exportdaten!AJ8<>"",Exportdaten!AJ8,"") -> Graz | T8: =IF(Exportdaten!AK8<>"",Exportdaten!AK8,"") | U8: =IF(Exportdaten!AL8<>"",Exportdaten!AL8,"") | V8: =IF(Exportdaten!AM8<>"",Exportdaten!AM8,"") -> ÖSTERREICH
A9: =IF(Exportdaten!A9<>"",Exportdaten!A9,"") -> 10500298 | B9: =IF(Exportdaten!B9<>"",Exportdaten!B9,"") | C9: =IF(Exportdaten!C9<>"",Exportdaten!C9,"") -> Herrn | D9: =IF(Exportdaten!D9<>"",Exportdaten!D9,"") | E9: =IF(Exportdaten!E9<>"",Exportdaten!E9,"") | F9: =IF(Exportdaten!F9<>"",Exportdaten!F9,"") | G9: =IF(Exportdaten!G9<>"",Exportdaten!G9,"") -> Matthias | H9: =IF(Exportdaten!H9<>"",Exportdaten!H9,"") | ... N9: =IF(Exportdaten!N9<>"",Exportdaten!N9,"") | O9: =IF(Exportdaten!AF9<>"",Exportdaten!AF9,"") -> postalisch | P9: =IF(Exportdaten!AG9<>"",Exportdaten!AG9,"") -> Privatadresse | Q9: =IF(Exportdaten!AH9<>"",Exportdaten!AH9,"") -> Raimundgasse 2/1 | R9: =IF(Exportdaten!AI9<>"",Exportdaten!AI9,"") -> 8010 | S9: =IF(Exportdaten!AJ9<>"",Exportdaten!AJ9,"") -> Graz | T9: =IF(Exportdaten!AK9<>"",Exportdaten!AK9,"") | U9: =IF(Exportdaten!AL9<>"",Exportdaten!AL9,"") | V9: =IF(Exportdaten!AM9<>"",Exportdaten!AM9,"") -> ÖSTERREICH
A10: =IF(Exportdaten!A10<>"",Exportdaten!A10,"") -> 10500022 | B10: =IF(Exportdaten!B10<>"",Exportdaten!B10,"") | C10: =IF(Exportdaten!C10<>"",Exportdaten!C10,"") -> Herrn | D10: =IF(Exportdaten!D10<>"",Exportdaten!D10,"") | E10: =IF(Exportdaten!E10<>"",Exportdaten!E10,"") -> DI (FH) | F10: =IF(Exportdaten!F10<>"",Exportdaten!F10,"") | G10: =IF(Exportdaten!G10<>"",Exportdaten!G10,"") -> David | H10: =IF(Exportdaten!H10<>"",Exportdaten!H10,"") | ... N10: =IF(Exportdaten!N10<>"",Exportdaten!N10,"") | O10: =IF(Exportdaten!AF10<>"",Exportdaten!AF10,"") -> postalisch | P10: =IF(Exportdaten!AG10<>"",Exportdaten!AG10,"") -> Privatadresse | Q10: =IF(Exportdaten!AH10<>"",Exportdaten!AH10,"") -> Dorfstraße 58 | R10: =IF(Exportdaten!AI10<>"",Exportdaten!AI10,"") -> 8403 | S10: =IF(Exportdaten!AJ10<>"",Exportdaten!AJ10,"") -> Sankt Margarethen bei Lebring | T10: =IF(Exportdaten!AK10<>"",Exportdaten!AK10,"") | U10: =IF(Exportdaten!AL10<>"",Exportdaten!AL10,"") | V10: =IF(Exportdaten!AM10<>"",Exportdaten!AM10,"") -> ÖSTERREICH
A11: =IF(Exportdaten!A11<>"",Exportdaten!A11,"") -> 13101359 | B11: =IF(Exportdaten!B11<>"",Exportdaten!B11,"") | C11: =IF(Exportdaten!C11<>"",Exportdaten!C11,"") -> Herrn | D11: =IF(Exportdaten!D11<>"",Exportdaten!D11,"") -> RA | E11: =IF(Exportdaten!E11<>"",Exportdaten!E11,"") -> Mag. | F11: =IF(Exportdaten!F11<>"",Exportdaten!F11,"") | G11: =IF(Exportdaten!G11<>"",Exportdaten!G11,"") -> Stefan | H11: =IF(Exportdaten!H11<>"",Exportdaten!H11,"") -> Albert | ... N11: =IF(Exportdaten!N11<>"",Exportdaten!N11,"") | O11: =IF(Exportdaten!AF11<>"",Exportdaten!AF11,"") -> postalisch | P11: =IF(Exportdaten!AG11<>"",Exportdaten!AG11,"") -> Privatadresse | Q11: =IF(Exportdaten!AH11<>"",Exportdaten!AH11,"") -> Bergerweg 3 | R11: =IF(Exportdaten!AI11<>"",Exportdaten!AI11,"") -> 4212 | S11: =IF(Exportdaten!AJ11<>"",Exportdaten!AJ11,"") -> Neumarkt im Mühlkreis | T11: =IF(Exportdaten!AK11<>"",Exportdaten!AK11,"") | U11: =IF(Exportdaten!AL11<>"",Exportdaten!AL11,"") | V11: =IF(Exportdaten!AM11<>"",Exportdaten!AM11,"") -> ÖSTERREICH
A12: =IF(Exportdaten!A12<>"",Exportdaten!A12,"") -> 10500121 | B12: =IF(Exportdaten!B12<>"",Exportdaten!B12,"") | C12: =IF(Exportdaten!C12<>"",Exportdaten!C12,"") -> Herrn | D12: =IF(Exportdaten!D12<>"",Exportdaten!D12,"") | E12: =IF(Exportdaten!E12<>"",Exportdaten!E12,"") -> Dr. | F12: =IF(Exportdaten!F12<>"",Exportdaten!F12,"") | G12: =IF(Exportdaten!G12<>"",Exportdaten!G12,"") -> Reinhold | H12: =IF(Exportdaten!H12<>"",Exportdaten!H12,"") | ... N12: =IF(Exportdaten!N12<>"",Exportdaten!N12,"") | O12: =IF(Exportdaten!AF12<>"",Exportdaten!AF12,"") -> postalisch | P12: =IF(Exportdaten!AG12<>"",Exportdaten!AG12,"") -> Privatadresse | Q12: =IF(Exportdaten!AH12<>"",Exportdaten!AH12,"") -> Schulweg 5A | R12: =IF(Exportdaten!AI12<>"",Exportdaten!AI12,"") -> 6973 | S12: =IF(Exportdaten!AJ12<>"",Exportdaten!AJ12,"") -> Höchst | T12: =IF(Exportdaten!AK12<>"",Exportdaten!AK12,"") | U12: =IF(Exportdaten!AL12<>"",Exportdaten!AL12,"") | V12: =IF(Exportdaten!AM12<>"",Exportdaten!AM12,"") -> ÖSTERREICH
A13: =IF(Exportdaten!A13<>"",Exportdaten!A13,"") -> 10500100 | B13: =IF(Exportdaten!B13<>"",Exportdaten!B13,"") | C13: =IF(Exportdaten!C13<>"",Exportdaten!C13,"") -> Herrn | D13: =IF(Exportdaten!D13<>"",Exportdaten!D13,"") -> Prof. | E13: =IF(Exportdaten!E13<>"",Exportdaten!E13,"") -> Mag. | F13: =IF(Exportdaten!F13<>"",Exportdaten!F13,"") | G13: =IF(Exportdaten!G13<>"",Exportdaten!G13,"") -> Gebhard | H13: =IF(Exportdaten!H13<>"",Exportdaten!H13,"") | ... N13: =IF(Exportdaten!N13<>"",Exportdaten!N13,"") | O13: =IF(Exportdaten!AF13<>"",Exportdaten!AF13,"") -> postalisch | P13: =IF(Exportdaten!AG13<>"",Exportdaten!AG13,"") -> Privatadresse | Q13: =IF(Exportdaten!AH13<>"",Exportdaten!AH13,"") -> Schillerstraße 27a/1 | R13: =IF(Exportdaten!AI13<>"",Exportdaten!AI13,"") -> 8010 | S13: =IF(Exportdaten!AJ13<>"",Exportdaten!AJ13,"") -> Graz | T13: =IF(Exportdaten!AK13<>"",Exportdaten!AK13,"") | U13: =IF(Exportdaten!AL13<>"",Exportdaten!AL13,"") | V13: =IF(Exportdaten!AM13<>"",Exportdaten!AM13,"") -> ÖSTERREICH
A14: =IF(Exportdaten!A14<>"",Exportdaten!A14,"") -> 11100786 | B14: =IF(Exportdaten!B14<>"",Exportdaten!B14,"") -> 786 | C14: =IF(Exportdaten!C14<>"",Exportdaten!C14,"") -> Herrn | D14: =IF(Exportdaten!D14<>"",Exportdaten!D14,"") -> Gschf. | E14: =IF(Exportdaten!E14<>"",Exportdaten!E14,"") -> Dipl.-Ing. | F14: =IF(Exportdaten!F14<>"",Exportdaten!F14,"") | G14: =IF(Exportdaten!G14<>"",Exportdaten!G14,"") -> Gernot | H14: =IF(Exportdaten!H14<>"",Exportdaten!H14,"") | ... N14: =IF(Exportdaten!N14<>"",Exportdaten!N14,"") -> MBA | O14: =IF(Exportdaten!AF14<>"",Exportdaten!AF14,"") -> postalisch | P14: =IF(Exportdaten!AG14<>"",Exportdaten!AG14,"") -> Privatadresse | Q14: =IF(Exportdaten!AH14<>"",Exportdaten!AH14,"") -> Krispl 70 | R14: =IF(Exportdaten!AI14<>"",Exportdaten!AI14,"") -> 5425 | S14: =IF(Exportdaten!AJ14<>"",Exportdaten!AJ14,"") -> Krispl | T14: =IF(Exportdaten!AK14<>"",Exportdaten!AK14,"") | U14: =IF(Exportdaten!AL14<>"",Exportdaten!AL14,"") | V14: =IF(Exportdaten!AM14<>"",Exportdaten!AM14,"") -> ÖSTERREICH
A15: =IF(Exportdaten!A15<>"",Exportdaten!A15,"") -> 10500044 | B15: =IF(Exportdaten!B15<>"",Exportdaten!B15,"") | C15: =IF(Exportdaten!C15<>"",Exportdaten!C15,"") -> Herrn | D15: =IF(Exportdaten!D15<>"",Exportdaten!D15,"") -> FA | E15: =IF(Exportdaten!E15<>"",Exportdaten!E15,"") -> Dr. | F15: =IF(Exportdaten!F15<>"",Exportdaten!F15,"") | G15: =IF(Exportdaten!G15<>"",Exportdaten!G15,"") -> Viktor | H15: =IF(Exportdaten!H15<>"",Exportdaten!H15,"") | ... N15: =IF(Exportdaten!N15<>"",Exportdaten!N15,"") | O15: =IF(Exportdaten!AF15<>"",Exportdaten!AF15,"") -> postalisch | P15: =IF(Exportdaten!AG15<>"",Exportdaten!AG15,"") -> Privatadresse | Q15: =IF(Exportdaten!AH15<>"",Exportdaten!AH15,"") -> Kresbach 138 | R15: =IF(Exportdaten!AI15<>"",Exportdaten!AI15,"") -> 8530 | S15: =IF(Exportdaten!AJ15<>"",Exportdaten!AJ15,"") -> Deutschlandsberg | T15: =IF(Exportdaten!AK15<>"",Exportdaten!AK15,"") | U15: =IF(Exportdaten!AL15<>"",Exportdaten!AL15,"") | V15: =IF(Exportdaten!AM15<>"",Exportdaten!AM15,"") -> ÖSTERREICH
A16: =IF(Exportdaten!A16<>"",Exportdaten!A16,"") -> 10500229 | B16: =IF(Exportdaten!B16<>"",Exportdaten!B16,"") | C16: =IF(Exportdaten!C16<>"",Exportdaten!C16,"") -> Herrn | D16: =IF(Exportdaten!D16<>"",Exportdaten!D16,"") -> RA | E16: =IF(Exportdaten!E16<>"",Exportdaten!E16,"") -> Mag. Dr. | F16: =IF(Exportdaten!F16<>"",Exportdaten!F16,"") | G16: =IF(Exportdaten!G16<>"",Exportdaten!G16,"") -> Lukas | H16: =IF(Exportdaten!H16<>"",Exportdaten!H16,"") | ... N16: =IF(Exportdaten!N16<>"",Exportdaten!N16,"") | O16: =IF(Exportdaten!AF16<>"",Exportdaten!AF16,"") -> postalisch | P16: =IF(Exportdaten!AG16<>"",Exportdaten!AG16,"") -> Privatadresse | Q16: =IF(Exportdaten!AH16<>"",Exportdaten!AH16,"") -> Max-Valier-Straße 24 | R16: =IF(Exportdaten!AI16<>"",Exportdaten!AI16,"") -> 39100 | S16: =IF(Exportdaten!AJ16<>"",Exportdaten!AJ16,"") -> Bozen | T16: =IF(Exportdaten!AK16<>"",Exportdaten!AK16,"") | U16: =IF(Exportdaten!AL16<>"",Exportdaten!AL16,"") | V16: =IF(Exportdaten!AM16<>"",Exportdaten!AM16,"") -> ITALIEN
A17: =IF(Exportdaten!A17<>"",Exportdaten!A17,"") -> 12200062 | B17: =IF(Exportdaten!B17<>"",Exportdaten!B17,"") | C17: =IF(Exportdaten!C17<>"",Exportdaten!C17,"") -> Herrn | D17: =IF(Exportdaten!D17<>"",Exportdaten!D17,"") | E17: =IF(Exportdaten!E17<>"",Exportdaten!E17,"") -> Dr. | F17: =IF(Exportdaten!F17<>"",Exportdaten!F17,"") | G17: =IF(Exportdaten!G17<>"",Exportdaten!G17,"") -> Markus | H17: =IF(Exportdaten!H17<>"",Exportdaten!H17,"") | ... N17: =IF(Exportdaten!N17<>"",Exportdaten!N17,"") | O17: =IF(Exportdaten!AF17<>"",Exportdaten!AF17,"") -> postalisch | P17: =IF(Exportdaten!AG17<>"",Exportdaten!AG17,"") | Q17: =IF(Exportdaten!AH17<>"",Exportdaten!AH17,"") | R17: =IF(Exportdaten!AI17<>"",Exportdaten!AI17,"") | S17: =IF(Exportdaten!AJ17<>"",Exportdaten!AJ17,"") | T17: =IF(Exportdaten!AK17<>"",Exportdaten!AK17,"") | U17: =IF(Exportdaten!AL17<>"",Exportdaten!AL17,"") | V17: =IF(Exportdaten!AM17<>"",Exportdaten!AM17,"")
... A173: =IF(Exportdaten!A173<>"",Exportdaten!A173,"") -> 10500096 | B173: =IF(Exportdaten!B173<>"",Exportdaten!B173,"") | C173: =IF(Exportdaten!C173<>"",Exportdaten!C173,"") -> Herrn | D173: =IF(Exportdaten!D173<>"",Exportdaten!D173,"") | E173: =IF(Exportdaten!E173<>"",Exportdaten!E173,"") | F173: =IF(Exportdaten!F173<>"",Exportdaten!F173,"") | G173: =IF(Exportdaten!G173<>"",Exportdaten!G173,"") -> Nikolaus | H173: =IF(Exportdaten!H173<>"",Exportdaten!H173,"") -> Zoltan | ... N173: =IF(Exportdaten!N173<>"",Exportdaten!N173,"") | O173: =IF(Exportdaten!AF173<>"",Exportdaten!AF173,"") -> postalisch | P173: =IF(Exportdaten!AG173<>"",Exportdaten!AG173,"") -> Privatadresse | Q173: =IF(Exportdaten!AH173<>"",Exportdaten!AH173,"") -> Entenplatz 12/11 | R173: =IF(Exportdaten!AI173<>"",Exportdaten!AI173,"") -> 8020 | S173: =IF(Exportdaten!AJ173<>"",Exportdaten!AJ173,"") -> Graz | T173: =IF(Exportdaten!AK173<>"",Exportdaten!AK173,"") | U173: =IF(Exportdaten!AL173<>"",Exportdaten!AL173,"") | V173: =IF(Exportdaten!AM173<>"",Exportdaten!AM173,"") -> ÖSTERREICH
